<?xml version="1.0" ?>
<sdf version="1.4">
    <model name="robot_thesis">
        <static>false</static>
        <link name="robot_base">
            <inertial>
                <pose>0 0 .1025 0 0 0</pose>
                <inertia>
                    <ixx>0.001</ixx>
                    <ixy>0.000</ixy>
                    <ixz>0.000</ixz>
                    <iyy>0.001</iyy>
                    <iyz>0.000</iyz>
                    <izz>0.001</izz>
                </inertia>
                <mass>1.0</mass>
            </inertial>
            <collision name="collision">
                <pose>0 0 .1025 0 0 0</pose>
                <geometry>
                    <box>
                        <size>.2 .2 .14</size>
                    </box>
                </geometry>
            </collision>
            <visual name="visual">
                <pose>0 0 .0625 0 0 -1.5707</pose>
                <geometry>
                    <mesh>
                        <uri>model://robot_thesis/meshs/dae/robot_base.dae</uri>
                    </mesh>
                </geometry>
            </visual>
            <collision name="caster_front_collision">
                <pose>-0.06 0 0.0325 0 0 0</pose>
                <geometry>
                    <sphere>
                        <radius>.0325</radius>
                    </sphere>
                </geometry>
                <surface>
                    <friction>
                        <ode>
                            <mu>0</mu>
                            <mu2>0</mu2>
                            <slip1>1.0</slip1>
                            <slip2>1.0</slip2>
                        </ode>
                    </friction>
                </surface>
            </collision>
            <!-- <visual name="caster_front_visual"><pose>0.06 0 0.0325 0 0 0</pose><geometry><sphere><radius>.0325</radius></sphere></geometry></visual>-->
            <collision name="caster_behind_collision">
                <pose>0.06 0 0.0325 0 0 0</pose>
                <geometry>
                    <sphere>
                        <radius>.0325</radius>
                    </sphere>
                </geometry>
                <!-- <visual name="caster_front_visual"><pose>0.06 0 0.0325 0 0 0</pose><geometry><sphere><radius>.0325</radius></sphere></geometry></visual>-->
                <surface>
                    <friction>
                        <ode>
                            <mu>0</mu>
                            <mu2>0</mu2>
                            <slip1>1.0</slip1>
                            <slip2>1.0</slip2>
                        </ode>
                    </friction>
                </surface>
            </collision>
        </link>
        <link name="robot_lidar">
            <inertial>
                <pose>-0.020 0 0.2 0 0 0</pose>
                <inertia>
                    <ixx>0.001</ixx>
                    <ixy>0.000</ixy>
                    <ixz>0.000</ixz>
                    <iyy>0.001</iyy>
                    <iyz>0.000</iyz>
                    <izz>0.001</izz>
                </inertia>
                <mass>0.125</mass>
            </inertial>
            <collision name="lidar_sensor_collision">
                <pose>-0.020 0 0.2 0 0 0</pose>
                <geometry>
                    <cylinder>
                        <radius>0.0508</radius>
                        <length>0.055</length>
                    </cylinder>
                </geometry>
            </collision>
            <sensor name="hls_lfcd_lds" type="ray">
                <always_on>1</always_on>
                <visualize>0</visualize>
                <pose>-0.032 0 0.171 0 0 0</pose>
                <update_rate>1800</update_rate>
                <ray>
                    <scan>
                        <horizontal>
                            <samples>360</samples>
                            <resolution>1.000000</resolution>
                            <min_angle>0.000000</min_angle>
                            <max_angle>6.280000</max_angle>
                        </horizontal>
                    </scan>
                    <range>
                        <min>0.120000</min>
                        <max>3.5</max>
                        <resolution>0.015000</resolution>
                    </range>
                    <noise>
                        <type>gaussian</type>
                        <mean>0.0</mean>
                        <stddev>0.01</stddev>
                    </noise>
                </ray>
            </sensor>
        </link>
        <link name="robot_leftwheel">
            <inertial>
                <pose>0 0.09 0.0325 -1.57 0 0</pose>
                <inertia>
                    <ixx>0.001</ixx>
                    <ixy>0.000</ixy>
                    <ixz>0.000</ixz>
                    <iyy>0.001</iyy>
                    <iyz>0.000</iyz>
                    <izz>0.001</izz>
                </inertia>
                <mass>0.1</mass>
            </inertial>
            <collision name="collision">
                <pose>0 0.09 0.0325 -1.57 0 0</pose>
                <geometry>
                    <cylinder>
                        <radius>.0325</radius>
                        <length>.026</length>
                    </cylinder>
                </geometry>
            </collision>
            <visual name="visual">
                <pose>0 0.09 0.0325 0 0  3.14  </pose>
                <geometry>
                    <mesh>
                        <uri>model://robot_thesis/meshs/dae/robot_wheel.dae</uri>
                    </mesh>
                </geometry>
            </visual>
        </link>
        <link name="robot_rightwheel">
            <inertial>
                <pose>0 -0.09 0.0325 -1.57 0 0</pose>
                <inertia>
                    <ixx>0.001</ixx>
                    <ixy>0.000</ixy>
                    <ixz>0.000</ixz>
                    <iyy>0.001</iyy>
                    <iyz>0.000</iyz>
                    <izz>0.001</izz>
                </inertia>
                <mass>0.1</mass>
            </inertial>
            <collision name="collision">
                <pose>0 -0.09 0.0325 -1.57 0 0</pose>
                <geometry>
                    <cylinder>
                        <radius>.0325</radius>
                        <length>.026</length>
                    </cylinder>
                </geometry>
            </collision>
            <visual name="visual">
                <pose>0 -0.09 0.0325 0 0 0</pose>
                <geometry>
                    <mesh>
                        <uri>model://robot_thesis/meshs/dae/robot_wheel.dae</uri>
                    </mesh>
                </geometry>
            </visual>
        </link>
        <joint name="left_wheel_hinge" type="revolute">
            <pose>0 0.09 0.0325 -1.57 0 0</pose>
            <child>robot_leftwheel</child>
            <parent>robot_base</parent>
            <axis>
                <xyz>0 1 0</xyz>
            </axis>
        </joint>
        <joint name="right_wheel_hinge" type="revolute">
            <pose>0 -0.09 0.0325 -1.57 0 0</pose>
            <child>robot_rightwheel</child>
            <parent>robot_base</parent>
            <axis>
                <xyz>0 1 0</xyz>
            </axis>
        </joint>
        <joint name="lidar_joint" type="fixed">
            <parent>robot_base</parent>
            <child>robot_lidar</child>
            <pose>0 0 0.2 0 0 0</pose>
            <axis>
                <xyz>0 0 1</xyz>
                <use_parent_model_frame>true</use_parent_model_frame>
            </axis>
        </joint>
    </model>
</sdf>